"""
PTE Retry Functionality Integration Tests
Demonstrates how to use retry functionality in actual test scenarios
"""
import pytest
import allure
import time
import random
from unittest.mock import Mock, patch
from core.retry import (
    retry,
    retry_with_condition,
    retry_on_exception,
    retry_on_false,
    retry_on_none,
    retry_on_empty
)
from core.logger import Log, generate_logid
from core.checker import Checker
from api.client import APIClient
from biz.department.user.operations import UserOperations


@allure.epic("PTE Framework")
@allure.feature("Retry Integration")
class TestRetryIntegration:
    """PTE Retry Functionality Integration Test Class"""
    
    @pytest.fixture(autouse=True)
    def setup(self):
        """Setup test environment"""
        # Initialize components
        self.api_client = APIClient()
        self.user_ops = UserOperations()
    
    @allure.story("API Call with Retry")
    @allure.severity(allure.severity_level.CRITICAL)
    def test_api_call_with_retry(self):
        """Test API call retry scenario"""
        # Set LogID
        logid = generate_logid()
        Log.set_logid(logid)
        
        Log.start_test("test_api_call_with_retry")
        
        try:
            Log.info("Starting API call retry scenario test")
            
            # Simulate unstable API call
            call_count = 0
            
            @retry_on_exception(
                exceptions=(ConnectionError, TimeoutError),
                max_attempts=3,
                delay=0.1
            )
            def unstable_api_call():
                nonlocal call_count
                call_count += 1
                
                # Simulate network instability
                if call_count < 3:
                    if random.random() < 0.7:  # 70% failure probability
                        raise ConnectionError(f"Network connection failed #{call_count}")
                
                return {"status": "success", "data": {"user_id": 12345}}
            
            # Execute API call
            result = unstable_api_call()
            
            # Verify result
            Checker.assert_equal(result["status"], "success")
            Checker.assert_equal(result["data"]["user_id"], 12345)
            Checker.assert_greater_equal(call_count, 1)
            
            Log.info("API call retry scenario test completed")
            
        except Exception as e:
            Log.error(f"test_api_call_with_retry test failed: {str(e)}")
            Log.end_test("test_api_call_with_retry", "FAILED")
            raise
        else:
            Log.end_test("test_api_call_with_retry", "PASSED")
    
    @allure.story("Database Operation with Retry")
    @allure.severity(allure.severity_level.CRITICAL)
    def test_database_operation_with_retry(self):
        """Test database operation retry scenario"""
        # Set LogID
        logid = generate_logid()
        Log.set_logid(logid)
        
        Log.start_test("test_database_operation_with_retry")
        
        try:
            Log.info("Starting database operation retry scenario test")
            
            # Simulate unstable database connection
            call_count = 0
            
            @retry_on_exception(
                exceptions=(Exception,),
                max_attempts=3,
                delay=0.1,
                strategy="exponential"
            )
            def database_operation():
                nonlocal call_count
                call_count += 1
                
                # Simulate database connection issues
                if call_count < 3:
                    raise Exception(f"Database connection failed #{call_count}")
                
                return {"affected_rows": 1, "status": "success"}
            
            # Execute database operation
            result = database_operation()
            
            # Verify result
            Checker.assert_equal(result["status"], "success")
            Checker.assert_equal(result["affected_rows"], 1)
            Checker.assert_greater_equal(call_count, 1)
            
            Log.info("Database operation retry scenario test completed")
            
        except Exception as e:
            Log.error(f"test_database_operation_with_retry test failed: {str(e)}")
            Log.end_test("test_database_operation_with_retry", "FAILED")
            raise
        else:
            Log.end_test("test_database_operation_with_retry", "PASSED")
    
    @allure.story("Async Task Wait with Retry")
    @allure.severity(allure.severity_level.CRITICAL)
    def test_async_task_wait_with_retry(self):
        """Test async task wait retry scenario"""
        # Set LogID
        logid = generate_logid()
        Log.set_logid(logid)
        
        Log.start_test("test_async_task_wait_with_retry")
        
        try:
            Log.info("Starting async task wait retry scenario test")
            
            # Simulate async task status check
            task_status = "pending"
            check_count = 0
            
            @retry_with_condition(
                condition=lambda result: result.get("status") == "completed",
                max_attempts=5,
                delay=0.2
            )
            def check_task_status():
                nonlocal task_status, check_count
                check_count += 1
                
                # Simulate task status change
                if check_count >= 3:
                    task_status = "completed"
                
                return {"status": task_status, "progress": check_count * 20}
            
            # Check task status
            result = check_task_status()
            
            # Verify result
            Checker.assert_equal(result["status"], "completed")
            Checker.assert_greater_equal(result["progress"], 60)
            Checker.assert_greater_equal(check_count, 3)
            
            Log.info("Async task wait retry scenario test completed")
            
        except Exception as e:
            Log.error(f"test_async_task_wait_with_retry test failed: {str(e)}")
            Log.end_test("test_async_task_wait_with_retry", "FAILED")
            raise
        else:
            Log.end_test("test_async_task_wait_with_retry", "PASSED")
    
    @allure.story("File Operation with Retry")
    @allure.severity(allure.severity_level.CRITICAL)
    def test_file_operation_with_retry(self):
        """Test file operation retry scenario"""
        # Set LogID
        logid = generate_logid()
        Log.set_logid(logid)
        
        Log.start_test("test_file_operation_with_retry")
        
        try:
            Log.info("Starting file operation retry scenario test")
            
            # Simulate unstable file system
            call_count = 0
            
            @retry_on_exception(
                exceptions=(FileNotFoundError, PermissionError),
                max_attempts=3,
                delay=0.1
            )
            def file_operation():
                nonlocal call_count
                call_count += 1
                
                # Simulate file system issues
                if call_count < 3:
                    raise FileNotFoundError(f"File not found #{call_count}")
                
                return {"content": "file content", "size": 1024}
            
            # Execute file operation
            result = file_operation()
            
            # Verify result
            Checker.assert_equal(result["content"], "file content")
            Checker.assert_equal(result["size"], 1024)
            Checker.assert_greater_equal(call_count, 1)
            
            Log.info("File operation retry scenario test completed")
            
        except Exception as e:
            Log.error(f"test_file_operation_with_retry test failed: {str(e)}")
            Log.end_test("test_file_operation_with_retry", "FAILED")
            raise
        else:
            Log.end_test("test_file_operation_with_retry", "PASSED")
    
    @allure.story("Data Validation with Retry")
    @allure.severity(allure.severity_level.CRITICAL)
    def test_data_validation_with_retry(self):
        """Test data validation retry scenario"""
        # Set LogID
        logid = generate_logid()
        Log.set_logid(logid)
        
        Log.start_test("test_data_validation_with_retry")
        
        try:
            Log.info("Starting data validation retry scenario test")
            
            # Simulate data validation process
            validation_count = 0
            
            @retry_on_false(max_attempts=4, delay=0.1)
            def validate_data():
                nonlocal validation_count
                validation_count += 1
                
                # Simulate data validation failure
                if validation_count < 3:
                    return False
                
                return True
            
            # Execute data validation
            result = validate_data()
            
            # Verify result
            Checker.assert_true(result is True)
            Checker.assert_greater_equal(validation_count, 3)
            
            Log.info("Data validation retry scenario test completed")
            
        except Exception as e:
            Log.error(f"test_data_validation_with_retry test failed: {str(e)}")
            Log.end_test("test_data_validation_with_retry", "FAILED")
            raise
        else:
            Log.end_test("test_data_validation_with_retry", "PASSED")
    
    @allure.story("Resource Availability with Retry")
    @allure.severity(allure.severity_level.CRITICAL)
    def test_resource_availability_with_retry(self):
        """Test resource availability retry scenario"""
        # Set LogID
        logid = generate_logid()
        Log.set_logid(logid)
        
        Log.start_test("test_resource_availability_with_retry")
        
        try:
            Log.info("Starting resource availability retry scenario test")
            
            # Simulate resource check
            check_count = 0
            
            @retry_on_false(max_attempts=5, delay=0.2)
            def check_resource():
                nonlocal check_count
                check_count += 1
                
                # Simulate resource unavailability
                if check_count < 4:
                    return False
                
                return True
            
            # Check resource availability
            result = check_resource()
            
            # Verify result
            Checker.assert_true(result is True)
            Checker.assert_greater_equal(check_count, 4)
            
            Log.info("Resource availability retry scenario test completed")
            
        except Exception as e:
            Log.error(f"test_resource_availability_with_retry test failed: {str(e)}")
            Log.end_test("test_resource_availability_with_retry", "FAILED")
            raise
        else:
            Log.end_test("test_resource_availability_with_retry", "PASSED")
    
    @allure.story("Complex Business Logic with Retry")
    @allure.severity(allure.severity_level.CRITICAL)
    def test_complex_business_logic_with_retry(self):
        """Test complex business logic retry scenario"""
        # Set LogID
        logid = generate_logid()
        Log.set_logid(logid)
        
        Log.start_test("test_complex_business_logic_with_retry")
        
        try:
            Log.info("Starting complex business logic retry scenario test")
            
            # Simulate complex business logic
            step_count = 0
            
            @retry_on_exception(
                exceptions=(ValueError, RuntimeError),
                max_attempts=3,
                delay=0.1
            )
            def complex_business_logic():
                nonlocal step_count
                step_count += 1
                
                # Simulate business logic failure
                if step_count < 3:
                    if step_count == 1:
                        raise ValueError("Business rule validation failed")
                    else:
                        raise RuntimeError("Data processing exception")
                
                return {"status": "success", "processed_items": 100}
            
            # Execute complex business logic
            result = complex_business_logic()
            
            # Verify result
            Checker.assert_equal(result["status"], "success")
            Checker.assert_equal(result["processed_items"], 100)
            Checker.assert_greater_equal(step_count, 3)
            
            Log.info("Complex business logic retry scenario test completed")
            
        except Exception as e:
            Log.error(f"test_complex_business_logic_with_retry test failed: {str(e)}")
            Log.end_test("test_complex_business_logic_with_retry", "FAILED")
            raise
        else:
            Log.end_test("test_complex_business_logic_with_retry", "PASSED")
    
    @allure.story("Timeout Handling with Retry")
    @allure.severity(allure.severity_level.CRITICAL)
    def test_timeout_handling_with_retry(self):
        """Test timeout handling retry scenario"""
        # Set LogID
        logid = generate_logid()
        Log.set_logid(logid)
        
        Log.start_test("test_timeout_handling_with_retry")
        
        try:
            Log.info("Starting timeout handling retry scenario test")
            
            # Simulate timeout operation
            attempt_count = 0
            
            @retry_on_exception(
                exceptions=(TimeoutError,),
                max_attempts=3,
                delay=0.1,
                timeout=0.5
            )
            def timeout_operation():
                nonlocal attempt_count
                attempt_count += 1
                
                # Simulate timeout
                if attempt_count < 3:
                    time.sleep(0.6)  # Exceed timeout
                
                return {"status": "completed", "duration": 0.1}
            
            # Execute timeout operation
            result = timeout_operation()
            
            # Verify result
            Checker.assert_equal(result["status"], "completed")
            Checker.assert_greater_equal(attempt_count, 1)
            
            Log.info("Timeout handling retry scenario test completed")
            
        except Exception as e:
            Log.error(f"test_timeout_handling_with_retry test failed: {str(e)}")
            Log.end_test("test_timeout_handling_with_retry", "FAILED")
            raise
        else:
            Log.end_test("test_timeout_handling_with_retry", "PASSED")
