"""
PTE Retry功能集成测试
展示在实际测试场景中如何使用retry功能
"""
import pytest
import allure
import time
import random
from unittest.mock import Mock, patch
from core.retry import (
    retry,
    retry_with_condition,
    retry_on_exception,
    retry_on_false,
    retry_on_none,
    retry_on_empty
)
from core.logger import Log, generate_logid
from api.client import APIClient
from biz.department.user.operations import UserOperations


@allure.epic("PTE Framework")
@allure.feature("Retry Integration")
class TestRetryIntegration:
    """PTE Retry功能集成测试类"""
    
    @pytest.fixture(autouse=True)
    def setup(self):
        """Setup test environment"""
        # 初始化组件
        self.api_client = APIClient()
        self.user_ops = UserOperations()
    
    @allure.story("API Call with Retry")
    @allure.severity(allure.severity_level.CRITICAL)
    def test_api_call_with_retry(self):
        """测试API调用重试场景"""
        # 设置LogID
        logid = generate_logid()
        Log.set_logid(logid)
        
        Log.start_test("test_api_call_with_retry")
        
        try:
            Log.info("开始测试API调用重试场景")
            
            # 模拟不稳定的API调用
            call_count = 0
            
            @retry_on_exception(
                exceptions=(ConnectionError, TimeoutError),
                max_attempts=3,
                delay=0.1
            )
            def unstable_api_call():
                nonlocal call_count
                call_count += 1
                
                # 模拟网络不稳定
                if call_count < 3:
                    if random.random() < 0.7:  # 70%概率失败
                        raise ConnectionError(f"网络连接失败 #{call_count}")
                
                return {"status": "success", "data": {"user_id": 12345}}
            
            # 执行API调用
            result = unstable_api_call()
            
            # 验证结果
            assert result["status"] == "success"
            assert result["data"]["user_id"] == 12345
            assert call_count >= 1
            
            Log.info("API调用重试场景测试完成")
            
        except Exception as e:
            Log.error(f"test_api_call_with_retry test failed: {str(e)}")
            Log.end_test("test_api_call_with_retry", "FAILED")
            raise
        else:
            Log.end_test("test_api_call_with_retry", "PASSED")
    
    @allure.story("Database Operation with Retry")
    @allure.severity(allure.severity_level.CRITICAL)
    def test_database_operation_with_retry(self):
        """测试数据库操作重试场景"""
        # 设置LogID
        logid = generate_logid()
        Log.set_logid(logid)
        
        Log.start_test("test_database_operation_with_retry")
        
        try:
            Log.info("开始测试数据库操作重试场景")
            
            # 模拟数据库连接不稳定
            call_count = 0
            
            @retry_on_exception(
                exceptions=(Exception,),
                max_attempts=3,
                delay=0.1,
                strategy="exponential"
            )
            def database_operation():
                nonlocal call_count
                call_count += 1
                
                # 模拟数据库连接问题
                if call_count < 3:
                    raise Exception(f"数据库连接失败 #{call_count}")
                
                return {"affected_rows": 1, "status": "success"}
            
            # 执行数据库操作
            result = database_operation()
            
            # 验证结果
            assert result["status"] == "success"
            assert result["affected_rows"] == 1
            assert call_count >= 1
            
            Log.info("数据库操作重试场景测试完成")
            
        except Exception as e:
            Log.error(f"test_database_operation_with_retry test failed: {str(e)}")
            Log.end_test("test_database_operation_with_retry", "FAILED")
            raise
        else:
            Log.end_test("test_database_operation_with_retry", "PASSED")
    
    @allure.story("Async Task Wait with Retry")
    @allure.severity(allure.severity_level.CRITICAL)
    def test_async_task_wait_with_retry(self):
        """测试异步任务等待重试场景"""
        # 设置LogID
        logid = generate_logid()
        Log.set_logid(logid)
        
        Log.start_test("test_async_task_wait_with_retry")
        
        try:
            Log.info("开始测试异步任务等待重试场景")
            
            # 模拟异步任务状态检查
            task_status = "pending"
            check_count = 0
            
            @retry_with_condition(
                condition=lambda result: result.get("status") == "completed",
                max_attempts=5,
                delay=0.2
            )
            def check_task_status():
                nonlocal task_status, check_count
                check_count += 1
                
                # 模拟任务状态变化
                if check_count >= 3:
                    task_status = "completed"
                
                return {"status": task_status, "progress": check_count * 20}
            
            # 检查任务状态
            result = check_task_status()
            
            # 验证结果
            assert result["status"] == "completed"
            assert result["progress"] >= 60
            assert check_count >= 3
            
            Log.info("异步任务等待重试场景测试完成")
            
        except Exception as e:
            Log.error(f"test_async_task_wait_with_retry test failed: {str(e)}")
            Log.end_test("test_async_task_wait_with_retry", "FAILED")
            raise
        else:
            Log.end_test("test_async_task_wait_with_retry", "PASSED")
    
    @allure.story("File Operation with Retry")
    @allure.severity(allure.severity_level.CRITICAL)
    def test_file_operation_with_retry(self):
        """测试文件操作重试场景"""
        # 设置LogID
        logid = generate_logid()
        Log.set_logid(logid)
        
        Log.start_test("test_file_operation_with_retry")
        
        try:
            Log.info("开始测试文件操作重试场景")
            
            # 模拟文件系统不稳定
            call_count = 0
            
            @retry_on_exception(
                exceptions=(FileNotFoundError, PermissionError),
                max_attempts=3,
                delay=0.1
            )
            def file_operation():
                nonlocal call_count
                call_count += 1
                
                # 模拟文件系统问题
                if call_count < 3:
                    raise FileNotFoundError(f"文件不存在 #{call_count}")
                
                return {"content": "file content", "size": 1024}
            
            # 执行文件操作
            result = file_operation()
            
            # 验证结果
            assert result["content"] == "file content"
            assert result["size"] == 1024
            assert call_count >= 1
            
            Log.info("文件操作重试场景测试完成")
            
        except Exception as e:
            Log.error(f"test_file_operation_with_retry test failed: {str(e)}")
            Log.end_test("test_file_operation_with_retry", "FAILED")
            raise
        else:
            Log.end_test("test_file_operation_with_retry", "PASSED")
    
    @allure.story("Data Validation with Retry")
    @allure.severity(allure.severity_level.CRITICAL)
    def test_data_validation_with_retry(self):
        """测试数据验证重试场景"""
        # 设置LogID
        logid = generate_logid()
        Log.set_logid(logid)
        
        Log.start_test("test_data_validation_with_retry")
        
        try:
            Log.info("开始测试数据验证重试场景")
            
            # 模拟数据验证过程
            validation_count = 0
            
            @retry_on_false(max_attempts=4, delay=0.1)
            def validate_data():
                nonlocal validation_count
                validation_count += 1
                
                # 模拟数据验证失败
                if validation_count < 3:
                    return False
                
                return True
            
            # 执行数据验证
            result = validate_data()
            
            # 验证结果
            assert result is True
            assert validation_count >= 3
            
            Log.info("数据验证重试场景测试完成")
            
        except Exception as e:
            Log.error(f"test_data_validation_with_retry test failed: {str(e)}")
            Log.end_test("test_data_validation_with_retry", "FAILED")
            raise
        else:
            Log.end_test("test_data_validation_with_retry", "PASSED")
    
    @allure.story("Resource Availability with Retry")
    @allure.severity(allure.severity_level.CRITICAL)
    def test_resource_availability_with_retry(self):
        """测试资源可用性重试场景"""
        # 设置LogID
        logid = generate_logid()
        Log.set_logid(logid)
        
        Log.start_test("test_resource_availability_with_retry")
        
        try:
            Log.info("开始测试资源可用性重试场景")
            
            # 模拟资源检查
            check_count = 0
            
            @retry_on_false(max_attempts=5, delay=0.2)
            def check_resource():
                nonlocal check_count
                check_count += 1
                
                # 模拟资源不可用
                if check_count < 4:
                    return False
                
                return True
            
            # 检查资源可用性
            result = check_resource()
            
            # 验证结果
            assert result is True
            assert check_count >= 4
            
            Log.info("资源可用性重试场景测试完成")
            
        except Exception as e:
            Log.error(f"test_resource_availability_with_retry test failed: {str(e)}")
            Log.end_test("test_resource_availability_with_retry", "FAILED")
            raise
        else:
            Log.end_test("test_resource_availability_with_retry", "PASSED")
    
    @allure.story("Complex Business Logic with Retry")
    @allure.severity(allure.severity_level.CRITICAL)
    def test_complex_business_logic_with_retry(self):
        """测试复杂业务逻辑重试场景"""
        # 设置LogID
        logid = generate_logid()
        Log.set_logid(logid)
        
        Log.start_test("test_complex_business_logic_with_retry")
        
        try:
            Log.info("开始测试复杂业务逻辑重试场景")
            
            # 模拟复杂的业务逻辑
            step_count = 0
            
            @retry_on_exception(
                exceptions=(ValueError, RuntimeError),
                max_attempts=3,
                delay=0.1
            )
            def complex_business_logic():
                nonlocal step_count
                step_count += 1
                
                # 模拟业务逻辑失败
                if step_count < 3:
                    if step_count == 1:
                        raise ValueError("业务规则验证失败")
                    else:
                        raise RuntimeError("数据处理异常")
                
                return {"status": "success", "processed_items": 100}
            
            # 执行复杂业务逻辑
            result = complex_business_logic()
            
            # 验证结果
            assert result["status"] == "success"
            assert result["processed_items"] == 100
            assert step_count >= 3
            
            Log.info("复杂业务逻辑重试场景测试完成")
            
        except Exception as e:
            Log.error(f"test_complex_business_logic_with_retry test failed: {str(e)}")
            Log.end_test("test_complex_business_logic_with_retry", "FAILED")
            raise
        else:
            Log.end_test("test_complex_business_logic_with_retry", "PASSED")
    
    @allure.story("Timeout Handling with Retry")
    @allure.severity(allure.severity_level.CRITICAL)
    def test_timeout_handling_with_retry(self):
        """测试超时处理重试场景"""
        # 设置LogID
        logid = generate_logid()
        Log.set_logid(logid)
        
        Log.start_test("test_timeout_handling_with_retry")
        
        try:
            Log.info("开始测试超时处理重试场景")
            
            # 模拟超时操作
            attempt_count = 0
            
            @retry_on_exception(
                exceptions=(TimeoutError,),
                max_attempts=3,
                delay=0.1,
                timeout=0.5
            )
            def timeout_operation():
                nonlocal attempt_count
                attempt_count += 1
                
                # 模拟超时
                if attempt_count < 3:
                    time.sleep(0.6)  # 超过超时时间
                
                return {"status": "completed", "duration": 0.1}
            
            # 执行超时操作
            result = timeout_operation()
            
            # 验证结果
            assert result["status"] == "completed"
            assert attempt_count >= 1
            
            Log.info("超时处理重试场景测试完成")
            
        except Exception as e:
            Log.error(f"test_timeout_handling_with_retry test failed: {str(e)}")
            Log.end_test("test_timeout_handling_with_retry", "FAILED")
            raise
        else:
            Log.end_test("test_timeout_handling_with_retry", "PASSED")
